Workbook
Name Academic_Date: Form_Setup!$B$8:$C$8
Name Academic_End_Date: Form_Setup!$C$8
Name Academic_End_Date: Form_Setup!$C$8
Name Academic_End_Date: Form_Setup!$C$8
Name Academic_End_Date: Form_Setup!$C$8
Name Academic_End_Year: constants!$E$2
Name Academic_End_Year: constants!$E$2
Name Academic_End_Year: constants!$E$2
Name Academic_End_Year: constants!$E$2
Name Academic_Start_Date: Form_Setup!$B$8
Name Academic_Start_Date: Form_Setup!$B$8
Name Academic_Start_Date: Form_Setup!$B$8
Name Academic_Start_Date: Form_Setup!$B$8
Name Academic_Start_Year: constants!$D$2
Name Academic_Start_Year: constants!$D$2
Name Academic_Start_Year: constants!$D$2
Name Academic_Start_Year: constants!$D$2
Name AcademicYear_ID: constants!$B$2
Name AcademicYear_ID: constants!$B$2
Name AcademicYear_ID: constants!$B$2
Name AcademicYear_ID: constants!$B$2
Name AcademicYear_List: constants!$A$2:$B$2
Name AcademicYear_Name: constants!$A$2
Name AcademicYear_Name: constants!$A$2
Name AcademicYear_Name: constants!$A$2
Name AcademicYear_Name: constants!$A$2
Name Age_ID: constants!$A$91:$A$111
Name Age_List: constants!$A$91:$B$111
Name Age_List: constants!$A$91:$B$111
Name Age_List: constants!$A$91:$B$111
Name Age_List: constants!$A$91:$B$111
Name Age_Name: constants!$B$91:$B$111
Name Age_Name: constants!$B$91:$B$111
Name Age_Name: constants!$B$91:$B$111
Name Age_Name: constants!$B$91:$B$111
Name Attrition_ID: constants!$A$16:$A$22
Name Attrition_List: constants!$A$16:$B$22
Name Attrition_Name: constants!$B$16:$B$22
Name District_Name_EN: Form_Setup!$K$4
Name District_PCode: Form_Setup!$J$4
Name Document_Code: constants!$F$79:$F$96
Name Electricity_Availability: 'SA-2'!$D$85
Name Electricity_Availability: 'SA-2'!$D$85
Name Electricity_Availability: 'SA-2'!$D$85
Name Electricity_Availability: 'SA-2'!$D$85
Name ElectricityAvailability_ID: constants!$E$65:$E$72
Name ElectricityAvailability_List: constants!$E$65:$F$72
Name ElectricityAvailability_Name: constants!$F$65:$F$72
Name ExpenditureType_ID: Form_Setup!$I$8:$I$9
Name ExpenditureType_List: Form_Setup!$I$8:$J$9
Name ExpenditureType_Name: Form_Setup!$J$8:$J$9
Name Facility_ID: constants!$A$120:$A$149
Name Facility_List: constants!$A$120:$B$149
Name Facility_List: constants!$A$120:$B$149
Name Facility_List: constants!$A$120:$B$149
Name Facility_List: constants!$A$120:$B$149
Name Facility_Name: constants!$B$120:$B$149
Name Facility_Name: constants!$B$120:$B$149
Name Facility_Name: constants!$B$120:$B$149
Name Facility_Name: constants!$B$120:$B$149

Sheet Sheet1
B1: 41273 | C1: =UPPER(LEFT(TEXT(B1,D$1&D$1&D$1),1)) -> S | D1: =DL -> d | E1: =" " & C1 & " " & C2 & " " & C3 & " " & C4 & " " & C5 & " " & C6 & " " & C7 -> S M T W T F S
B2: 41274 | C2: =UPPER(LEFT(TEXT(B2,D$1&D$1&D$1),1)) -> M | E2: =" " & C2 & " " & C3 & " " & C4 & " " & C5 & " " & C6 & " " & C7 & " " & C8 -> M T W T F S S
B3: 41275 | C3: =UPPER(LEFT(TEXT(B3,D$1&D$1&D$1),1)) -> T
B4: 41276 | C4: =UPPER(LEFT(TEXT(B4,D$1&D$1&D$1),1)) -> W
B5: 41277 | C5: =UPPER(LEFT(TEXT(B5,D$1&D$1&D$1),1)) -> T
B6: 41278 | C6: =UPPER(LEFT(TEXT(B6,D$1&D$1&D$1),1)) -> F
B7: 41279 | C7: =UPPER(LEFT(TEXT(B7,D$1&D$1&D$1),1)) -> S
B8: 41280 | C8: =UPPER(LEFT(TEXT(B8,D$1&D$1&D$1),1)) -> S

Sheet constants
B1: Academic Year ID | D1: Academic Start Year | E1: Academic End Year | G1: Not Applicable Sign | AH1: Academic_Date | AN1: MyanmarLetter_ID | AO1: MyanmarLetter_MM | AP1: MyanmarLetter_EN | AQ1: MyanmarLetter_EnglishSymbol
A2: =Academic_Start_Year & "-" & Academic_End_Year -> 2013-2014 | B2: =Academic_End_Year -> 2014 | D2: =TEXT(Academic_Start_Date,"yyyy") -> 2013 | E2: =TEXT(Academic_End_Date,"yyyy") -> 2014 | G2: N/A | AH2: Academic_End_Date | AN2: 01 | AO2: က | AP2: KA | AQ2: A
AH3: Academic_End_Year | AN3: 02 | AO3: ခ | AP3: KHA | AQ3: B
AH4: Academic_Start_Date | AN4: 03 | AO4: ဂ | AP4: GA | AQ4: C | AW4: Academic_Date | AX4: =Form_Setup!$B$7:$C$7
AH5: Academic_Start_Year | AN5: 04 | AO5: ဃ | AP5: GHA | AQ5: D | AS5: NRCState_ID | AT5: NRCState_Name | AW5: Academic_End_Date | AX5: =Form_Setup!$C$7
AH6: AcademicYear_ID | AN6: 05 | AO6: င | AP6: NGA | AQ6: E | AS6: 1 | AT6: Kachin | AW6: Academic_End_Year | AX6: =constants!$E$2
P7: =IF(LEN(I26)=1,"0"& I26,""&I26) -> 01 | AH7: AcademicYear_List | AN7: 06 | AO7: စ | AP7: CA | AQ7: F | AS7: 2 | AT7: Kayah | AW7: Academic_Start_Date | AX7: =Form_Setup!$B$7
A8: Identity Type ID | B8: Identity Type_Code | C8: IdentityType_EN | D8: IdentityType_MM | E8: SchoolPost ID | F8: SchoolPost Name | G8: SchoolPost_SortCode | I8: LeaveType_ID | J8: LeaveType_Name | P8: 1 | T8: 1 | AB8: 1 | AH8: AcademicYear_Name | AJ8: 1 | AN8: 07 | AO8: ဆ | AP8: CHA | AQ8: G | AS8: 3 | AT8: Kayin | AW8: Academic_Start_Year | AX8: =constants!$D$2
A9: 1 | B9: n | C9: Naing | D9: နိုင် | E9: 1 | F9: School Principals | G9: 1 | I9: 1 | J9: Other Duty | N9: 1 | P9: 1 | T9: 1 | AH9: Age_ID | AN9: 08 | AO9: ဇ | AP9: JA | AQ9: H | AS9: 4 | AT9: Chin | AW9: AcademicYear_ID | AX9: =constants!$B$2
A10: 2 | B10: e | C10: Eaet | D10: ဧည့် | E10: 2 | F10: SAT | G10: 2 | I10: 2 | J10: Certified Leave | AH10: Age_List | AN10: 09 | AO10: ဈ | AP10: JHA | AQ10: I | AS10: 5 | AT10: Sagaing | AW10: AcademicYear_List | AX10: =constants!$A$2:$B$2
A11: 3 | B11: p | C11: Pu | D11: ပြု | E11: 3 | F11: SAT (Physical Training) | G11: 2 | I11: 3 | J11: Uncertified Leave | AH11: Age_Name | AN11: 10 | AO11: ဉ | AP11: NYA | AS11: 6 | AT11: Taninthayi | AW11: AcademicYear_Name | AX11: =constants!$A$2
A12: 4 | B12: y | C12: Yaryee | D12: ယာယီ | E12: 4 | F12: JAT | G12: 3 | AA12: Module_ID | AB12: Grade_ID | AC12: TextBook_ID | AD12: Subject_ID | AE12: TextBook_Name | AH12: Attrition_ID | AN12: 11 | AO12: ည | AP12: NNYA | AQ12: J | AS12: 7 | AT12: Bago | AW12: Age_ID | AX12: =constants!$A$91:$A$111
E13: 5 | F13: JAT (Physical Training) | G13: 3 | AA13: 0101 | AB13: 01 | AC13: 01 | AD13: 2 | AE13: မြန်မာစာ | AH13: Attrition_List | AN13: 12 | AO13: ဋ | AP13: TTA | AQ13: K | AS13: 8 | AT13: Magway | AW13: Age_List | AX13: =constants!$A$91:$B$111
E14: 6 | F14: JAT 2 | G14: 4 | AA14: 0116 | AB14: 01 | AC14: 16 | AD14: 3 | AE14: အင်္ဂလိပ်စာ | AH14: Attrition_Name | AN14: 13 | AO14: ဌ | AP14: TTHA | AQ14: L | AS14: 9 | AT14: Mandalay | AW14: Age_Name | AX14: =constants!$B$91:$B$111
A15: Attrition ID | B15: Type of Attrition | E15: 7 | F15: PAT | G15: 5 | AA15: 0117 | AB15: 01 | AC15: 17 | AD15: 4 | AE15: သင်္ချာ | AH15: District_Name_EN | AN15: 14 | AO15: ဍ | AP15: DDA | AQ15: M | AS15: 10 | AT15: Mon | AW15: Attrition_ID | AX15: =constants!$A$16:$A$22
A16: 1 | B16: Super Annulations | E16: 8 | F16: Office Clerk | G16: 6 | AA16: 0120 | AB16: 01 | AC16: 20 | AD16: 6 | AE16: သဘာဝသိပ္ပံ | AH16: District_PCode | AN16: 15 | AO16: ဎ | AP16: DDHA | AQ16: N | AS16: 11 | AT16: Rakine | AW16: Attrition_List | AX16: =constants!$A$16:$B$22
A17: 2 | B17: Service pension | E17: 9 | F17: JAT 3 | G17: 7 | AA17: 0123 | AB17: 01 | AC17: 23 | AD17: 14 | AE17: ဘဝတွက်တာကျွမ်းကျင်စရာ | AH17: DL | AN17: 16 | AO17: ဏ | AP17: NNA | AQ17: O | AS17: 12 | AT17: Yangon | AW17: Attrition_Name | AX17: =constants!$B$16:$B$22
A18: 3 | B18: Other pension | E18: 10 | F18: Cleaner/ Guard | G18: 8 | AA18: 0201 | AB18: 02 | AC18: 01 | AD18: 2 | AE18: မြန်မာစာ | AH18: Document_Code | AN18: 17 | AO18: တ | AP18: TA | AQ18: P | AS18: 13 | AT18: Shan | AW18: District_Name_EN | AX18: =Form_Setup!$K$3
A19: 4 | B19: Transfer to other dept | AA19: 0216 | AB19: 02 | AC19: 16 | AD19: 3 | AE19: အင်္ဂလိပ်စာ | AH19: Electricity_Availability | AN19: 18 | AO19: ထ | AP19: THA | AQ19: Q | AS19: 14 | AT19: Ayeyarwady | AW19: District_PCode | AX19: =Form_Setup!$J$3
A20: 5 | B20: Resign | AA20: 0217 | AB20: 02 | AC20: 17 | AD20: 4 | AE20: သင်္ချာ | AH20: ElectricityAvailability_ID | AN20: 19 | AO20: ဒ | AP20: DA | AQ20: R | AS20: 15 | AT20: Naypyitaw | AW20: DL | AX20: =INDEX(GET.WORKSPACE(37+NOW()*0),21)
A21: 6 | B21: Dismiss | AA21: 0220 | AB21: 02 | AC21: 20 | AD21: 6 | AE21: သဘာဝသိပ္ပံ | AH21: ElectricityAvailability_List | AN21: 20 | AO21: ဓ | AP21: DHA | AQ21: S | AW21: Document_Code | AX21: =constants!$F$79:$F$96
A22: 7 | B22: Deceased | AA22: 0223 | AB22: 02 | AC22: 23 | AD22: 14 | AE22: ဘဝတွက်တာကျွမ်းကျင်စရာ | AH22: ElectricityAvailability_Name | AN22: 21 | AO22: န | AP22: NA | AQ22: T | AW22: Electricity_Availability | AX22: ='SA-2'!$D$85
AA23: 0301 | AB23: 03 | AC23: 01 | AD23: 2 | AE23: မြန်မာစာ | AH23: ExpenditureType_ID | AN23: 22 | AO23: ပ | AP23: PA | AQ23: U | AW23: ElectricityAvailability_ID | AX23: =constants!$E$65:$E$72
A24: School Level ID | B24: School Level Short Name | C24: SchoolLevel_SortCode | AA24: 0316 | AB24: 03 | AC24: 16 | AD24: 3 | AE24: အင်္ဂလိပ်စာ | AH24: ExpenditureType_List | AN24: 23 | AO24: ဖ | AP24: PHA | AQ24: V | AW24: ElectricityAvailability_List | AX24: =constants!$E$65:$F$72
A25: 1 | B25: SHS | C25: 1 | I25: Grade_ID | J25: Grade_Name | K25: GradeSort_Code | AA25: 0317 | AB25: 03 | AC25: 17 | AD25: 4 | AE25: သင်္ချာ | AH25: ExpenditureType_Name | AN25: 24 | AO25: ဗ | AP25: BA | AQ25: W | AW25: ElectricityAvailability_Name | AX25: =constants!$F$65:$F$72
A26: 2 | B26: SMS | C26: 2 | I26: 01 | J26: Grade 1 | K26: 2 | AA26: 0320 | AB26: 03 | AC26: 20 | AD26: 6 | AE26: သဘာဝသိပ္ပံ | AH26: Form_ID | AN26: 25 | AO26: ဘ | AP26: BHA | AQ26: X | AW26: ExpenditureType_ID | AX26: =Form_Setup!$I$7:$I$8
A27: 3 | B27: SPS | C27: 3 | I27: 02 | J27: Grade 2 | K27: 3 | Q27: SectionID | R27: SectionName | S27: SectionSort_Code | U27: =IF(LEN(V28)=1,"0"& V28,""&V28) -> 01 | V27: TextBook_ID | W27: TextBook_EN | X27: TextBook_MM | Y27: Subject_ID | AA27: 0323 | AB27: 03 | AC27: 23 | AD27: 14 | AE27: ဘဝတွက်တာကျွမ်းကျင်စရာ | AH27: Form_List | AN27: 26 | AO27: မ | AP27: MA | AQ27: Y | AW27: ExpenditureType_List | AX27: =Form_Setup!$I$7:$J$8
A28: 4 | B28: Br- High | C28: 5 | I28: 03 | J28: Grade 3 | K28: 4 | Q28: 01 | R28: Special | S28: 1 | V28: 01 | W28: Myanmar | X28: မြန်မာစာ | Y28: 2 | AA28: 391 | AB28: 04 | AC28: 01 | AD28: 2 | AE28: မြန်မာစာ | AH28: Form_Name | AN28: 27 | AO28: ယ | AP28: YA | AQ28: Z | AW28: ExpenditureType_Name | AX28: =Form_Setup!$J$7:$J$8
A29: 5 | B29: Br-Mid | C29: 6 | I29: 04 | J29: Grade 4 | K29: 5 | Q29: 02 | R29: A | S29: 2 | V29: 02 | W29: Myanmar Reader | X29: မြန်မာဖတ်စာ | Y29: 2 | AA29: 0416 | AB29: 04 | AC29: 16 | AD29: 3 | AE29: အင်္ဂလိပ်စာ | AH29: FormPost_31 | AN29: 28 | AO29: ရ | AP29: RA | AQ29: AA | AW29: Facility_ID | AX29: =constants!$A$120:$A$149
A30: 6 | B30: Br-Pri | C30: 7 | I30: 05 | J30: Grade 5 | K30: 6 | Q30: 03 | R30: B | S30: 3 | V30: 03 | W30: Myanmar Grammar | X30: မြန်မာသဒ္ဒါ | Y30: 2 | AA30: 0417 | AB30: 04 | AC30: 17 | AD30: 4 | AE30: သင်္ချာ | AH30: FormPost_312_First | AN30: 29 | AO30: လ | AP30: LA | AQ30: BB | AW30: Facility_List | AX30: =constants!$A$120:$B$149
A31: 7 | B31: Af-High | C31: 8 | I31: 06 | J31: Grade 6 | K31: 7 | Q31: 04 | R31: C | S31: 4 | V31: 04 | W31: Myanmar Zartaka stories | X31: မြန်မာဇာတကဝတ္ထုတိုပျား | Y31: 2 | AA31: 0425 | AB31: 04 | AC31: 25 | AD31: 5 | AE31: ပထဝီဝင်သမိုင်း | AH31: FormPost_312_Second | AN31: 30 | AO31: ဝ | AP31: WA | AQ31: CC | AW31: Facility_Name | AX31: =constants!$B$120:$B$149
A32: 8 | B32: Af-Mid | C32: 9 | E32: 1 | I32: 07 | J32: Grade 7 | K32: 8 | Q32: 05 | R32: D | S32: 5 | V32: 05 | W32: Mahawtada | X32: မဟော်သဓာ | Y32: 2 | AA32: 0421 | AB32: 04 | AC32: 21 | AD32: 6 | AE32: အခြေခံသိပ္ပံ | AH32: FormPost_32 | AN32: 31 | AO32: သ | AP32: SA | AQ32: DD | AW32: Form_ID | AX32: =constants!$E$79:$E$96
A33: 9 | B33: Af-Pri | C33: 10 | I33: 08 | J33: Grade 8 | K33: 9 | Q33: 06 | R33: E | S33: 6 | V33: 06 | W33: Myanmar poems | X33: မြန်မာကဗျာ | Y33: 2 | AA33: 0423 | AB33: 04 | AC33: 23 | AD33: 14 | AE33: ဘဝတွက်တာကျွမ်းကျင်စရာ | AH33: FormPost_33 | AN33: 32 | AO33: ဟ | AP33: HA | AQ33: EE | AW33: Form_List | AX33: =constants!$E$78:$G$96
A34: 10 | B34: Post- Pri | C34: 4 | I34: 09 | J34: Grade 9 | K34: 10 | Q34: 07 | R34: F | S34: 7 | V34: 07 | W34: Myanmar selected poems | X34: မြန်မာကဗျာလက်ရွေးစဉ် | Y34: 2 | AA34: 0424 | AB34: 04 | AC34: 24 | AD34: 14 | AE34: ပြည်ထောင်စုစိတ်ဓာတ် | AH34: FormPost_34_Aug | AN34: 33 | AO34: ဠ | AP34: LLA | AQ34: FF | AW34: Form_Name | AX34: =constants!$G$79:$G$96
A35: 11 | B35: Monastic | C35: 11 | I35: 10 | J35: Grade 10 | K35: 11 | Q35: 08 | R35: G | S35: 8 | V35: 08 | W35: Compulsory Myanmar Prose | X35: ပင်ရင်းစကားပြေ | Y35: 2 | AA35: 0428 | AB35: 04 | AC35: 28 | AD35: 8 | AE35: မြန်မာ့သမိုင်း အတွဲ၂ | AH35: FormPost_34_Feb | AN35: 34 | AO35: အ | AP35: A | AQ35: GG | AW35: FormDate_31 | AX35: ='SA-1'!$P$114
A36: 12 | B36: Community | C36: 12 | I36: 11 | J36: Grade 11 | K36: 12 | Q36: 09 | R36: H | S36: 9 | V36: 09 | W36: Writing Myanmar Poetry | X36: မြန်မာကဗျာဖွဲ့နည်း | Y36: 2 | AA36: 0501 | AB36: 05 | AC36: 01 | AD36: 2 | AE36: မြန်မာစာ | AH36: FormPost_34_Nov | AN36: 35 | AO36: ဧ | AP36: E | AW36: FormPost_31 | AX36: ='SA-1'!$P$113
I37: 101 | J37: ECD | K37: 1 | Q37: 10 | R37: I | S37: 10 | V37: 10 | W37: Myanmar short stories | X37: မြန်မာဝတ္ထုတိုများ | Y37: 2 | AA37: 0516 | AB37: 05 | AC37: 16 | AD37: 3 | AE37: အင်္ဂလိပ်စာ | AH37: FormPost_37 | AN37: 36 | AO37: ဥ | AP37: U | AQ37: HH | AW37: FormPost_312_First | AX37: =PCET2_First!$AJ$8
Q38: 11 | R38: J | S38: 11 | V38: 11 | W38: Potetawwarda Pjou | X38: ပုတ္တောဝါဒပျို့ | Y38: 2 | AA38: 0517 | AB38: 05 | AC38: 17 | AD38: 4 | AE38: သင်္ချာ | AH38: FormPost_38 | AN38: 37 | AO38: A | AW38: FormPost_312_Second | AX38: =PCET2_Second!$AJ$8
A39: SchoolLevelExist _ID | B39: School Level Exist Name | Q39: 12 | R39: K | S39: 12 | V39: 12 | W39: Yaethe Play | X39: ရေသည်ပြဇာတ် | Y39: 2 | AA39: 0525 | AB39: 05 | AC39: 25 | AD39: 5 | AE39: ပထဝီဝင်သမိုင်း | AH39: FormPost_39 | AN39: 38 | AO39: B | AW39: FormPost_32 | AX39: ='SA-2'!$V$98
A40: 1 | B40: Pri | E40: LandOwnershipType_ID | F40: LandOwnershipType_Name | Q40: 13 | R40: L | S40: 13 | V40: 13 | W40: Mg Yin Mg, Ma Mae Ma | X40: မောင်ရင်မောင်မမယ်မ | Y40: 2 | AA40: 0521 | AB40: 05 | AC40: 21 | AD40: 6 | AE40: အခြေခံသိပ္ပံ | AH40: FormSignPost_List | AN40: 39 | AO40: C | AW40: FormPost_33 | AX40: ='SA-3'!$W$9
...

Sheet variables
A1: Selected Control Color | B1: Selected Control Name | C1: Selected_Ward_VT_ID | D1: Selected_Urban_Rural | E1: Selected_Village_ID
A2: 12646612 | C2: 110080180 | D2: 2 | E2: 195703
A4: Selected_School_Level | B4: Selected_School_Level_Exist | D4: TSIndex_SchoolID
A5: ='SA-1'!$C$22 -> 1 | B5: 6 | D5: =CLEAN(IFERROR(Township_Index & RIGHT(Selected_School_ID,6),"")) -> 180018001
A7: Selected_LandOwnership | B7: Selected_LandType
A8: ='SA-1'!$B$43 -> 1 | B8: ='SA-1'!$I$43 -> 2
A10: Selected_SchoolShiftType
A11: ='SA-1'!$D$36 -> 1
A13: Selected_SchoolMediaPlatform
A14: ='SA-1'!$B$101 -> 1

Sheet 3_Townships
C1: Welcome to the Township Education Management System. In order to use this program, click 'Options...' on the Message Bar and select 'Enable this content'. Alternatively, open the file with Macro Control from a Trusted Location.
A2: Township_ID | B2: TS_Pcode | C2: NEMIS_TS_Index | D2: Township_EN | E2: Township_MM | F2: SR_ID | G2: SR_PCode | H2: State_Region | I2: State_Region_MM | J2: D_PCode | K2: District | L2: MYA_INFO_TS_ID | M2: Source | N2: Remark
A3: 11001 | B3: MMR011001 | C3: 173 | D3: Mawlamyine | E3: မော်လမြိုင် | F3: 11 | G3: MMR011 | H3: Mon | I3: မွန်ပြည်နယ် | J3: MMR011D001 | K3: Mawlamyine | L3: ASIMMR011001 | M3: GAD, Aug 2012
A4: 11002 | B4: MMR011002 | C4: 174 | D4: Kyaikmaraw | E4: ကျိုက္မရော | F4: 11 | G4: MMR011 | H4: Mon | I4: မွန်ပြည်နယ် | J4: MMR011D001 | K4: Mawlamyine | L4: ASIMMR011002 | M4: GAD, Aug 2012
A5: 11003 | B5: MMR011003 | C5: 175 | D5: Chaungzon | E5: ချောင်းဆုံ | F5: 11 | G5: MMR011 | H5: Mon | I5: မွန်ပြည်နယ် | J5: MMR011D001 | K5: Mawlamyine | L5: ASIMMR011003 | M5: GAD, Aug 2012
A6: 11004 | B6: MMR011004 | C6: 176 | D6: Thanbyuzayat | E6: သံဖြူဇရပ် | F6: 11 | G6: MMR011 | H6: Mon | I6: မွန်ပြည်နယ် | J6: MMR011D001 | K6: Mawlamyine | L6: ASIMMR011004 | M6: GAD, Aug 2012
A7: 11005 | B7: MMR011005 | C7: 177 | D7: Mudon | E7: မုဒုံ | F7: 11 | G7: MMR011 | H7: Mon | I7: မွန်ပြည်နယ် | J7: MMR011D001 | K7: Mawlamyine | L7: ASIMMR011005 | M7: GAD, Aug 2012
A8: 11006 | B8: MMR011006 | C8: 178 | D8: Ye | E8: ရေး | F8: 11 | G8: MMR011 | H8: Mon | I8: မွန်ပြည်နယ် | J8: MMR011D001 | K8: Mawlamyine | L8: ASIMMR011006 | M8: GAD, Aug 2012
A9: 11007 | B9: MMR011007 | C9: 179 | D9: Thaton | E9: သထုံ | F9: 11 | G9: MMR011 | H9: Mon | I9: မွန်ပြည်နယ် | J9: MMR011D002 | K9: Thaton | L9: ASIMMR011007 | M9: GAD, Aug 2012
A10: 11008 | B10: MMR011008 | C10: 180 | D10: Paung | E10: ပေါင် | F10: 11 | G10: MMR011 | H10: Mon | I10: မွန်ပြည်နယ် | J10: MMR011D002 | K10: Thaton | L10: ASIMMR011008 | M10: GAD, Aug 2012
A11: 11009 | B11: MMR011009 | C11: 181 | D11: Kyaikto | E11: ကျိုက်ထို | F11: 11 | G11: MMR011 | H11: Mon | I11: မွန်ပြည်နယ် | J11: MMR011D002 | K11: Thaton | L11: ASIMMR011009 | M11: GAD, Aug 2012
A12: 11010 | B12: MMR011010 | C12: 182 | D12: Bilin | E12: ဘီးလင်း | F12: 11 | G12: MMR011 | H12: Mon | I12: မွန်ပြည်နယ် | J12: MMR011D002 | K12: Thaton | L12: ASIMMR011010 | M12: GAD, Aug 2012
A15: Sorted by TownshipID

Sheet 6_Village_Tracts
A1: Township_ID | B1: VT_ID | C1: Village_Tract_Name_EN | D1: Village_Tract_Name_MM | E1: TS_Pcode | F1: VT_PCode | G1: MYAINFO_VT_ID | H1: Source | I1: Remark | J1: Old_VT_PCode | K1: SR_ID
A2: 11001 | B2: 110010180 | C2: Hpar Auk | D2: ဖါးအောက် | E2: MMR011001 | F2: MMR011001018 | G2: ASIMMR011001018 | H2: GAD, Aug 2012 | K2: 11
A3: 11001 | B3: 110010010 | C3: Ka Toe | D3: ကတိုး | E3: MMR011001 | F3: MMR011001001 | G3: ASIMMR011001001 | H3: GAD, Aug 2012 | K3: 11
A4: 11001 | B4: 110010070 | C4: Kawt Hlar | D4: ကော့လှာ | E4: MMR011001 | F4: MMR011001007 | G4: ASIMMR011001007 | H4: GAD, Aug 2012 | K4: 11
A5: 11001 | B5: 110010060 | C5: Kawt Hnat | D5: ကော့နှပ် | E5: MMR011001 | F5: MMR011001006 | G5: ASIMMR011001006 | H5: GAD, Aug 2012 | K5: 11
A6: 11001 | B6: 110010170 | C6: Kawt Kha Mei | D6: ကော့ခမယ် | E6: MMR011001 | F6: MMR011001017 | G6: ASIMMR011001017 | H6: GAD, Aug 2012 | K6: 11
A7: 11001 | B7: 110010140 | C7: Kawt Kha Ni | D7: ကော့ခနိ | E7: MMR011001 | F7: MMR011001014 | G7: ASIMMR011001014 | H7: GAD, Aug 2012 | K7: 11
A8: 11001 | B8: 110010080 | C8: Kawt Pauk | D8: ကော့ပေါက် | E8: MMR011001 | F8: MMR011001008 | G8: ASIMMR011001008 | H8: GAD, Aug 2012 | K8: 11
A9: 11001 | B9: 110010050 | C9: Kawt Tun | D9: ကော့တွန် | E9: MMR011001 | F9: MMR011001005 | G9: ASIMMR011001005 | H9: GAD, Aug 2012 | K9: 11
A10: 11001 | B10: 110010020 | C10: Kawt Wein | D10: ကော့ဝိန် | E10: MMR011001 | F10: MMR011001002 | G10: ASIMMR011001002 | H10: GAD, Aug 2012 | K10: 11
A11: 11001 | B11: 110010160 | C11: Kyar Inn | D11: ကြာအင်း | E11: MMR011001 | F11: MMR011001016 | G11: ASIMMR011001016 | H11: GAD, Aug 2012 | K11: 11
A12: 11001 | B12: 110010100 | C12: Min Ywar | D12: မင်းရွာ | E12: MMR011001 | F12: MMR011001010 | G12: ASIMMR011001010 | H12: GAD, Aug 2012 | K12: 11
A13: 11001 | B13: 110010110 | C13: Mu Yaung | D13: မုရောင်း | E13: MMR011001 | F13: MMR011001011 | G13: ASIMMR011001011 | H13: GAD, Aug 2012 | K13: 11
... A174: 11006 | B174: 110060130 | C174: Han Gan | D174: ဟံဂံ | E174: MMR011006 | F174: MMR011006013 | G174: ASIMMR011006013 | H174: GAD, Aug 2012 | K174: 11
A175: 11006 | B175: 110060230 | C175: Hnin Sone (Lamaing Sub-township) | D175: နှင်းစုံ | E175: MMR011006 | F175: MMR011006023 | G175: ASIMMR011006023 | H175: GAD, Aug 2012 | I175: Renamedd from Hnin Sote | K175: 11
A176: 11006 | B176: 110060200 | C176: Hnit Kayin (Lamaing Sub-township) | D176: နှစ်ကရင် | E176: MMR011006 | F176: MMR011006020 | G176: ASIMMR011006020 | H176: GAD, Aug 2012 | K176: 11
A177: 11006 | B177: 110060270 | C177: Ka Byar (Khawzar Sub-township) | D177: ကဗျာ | E177: MMR011006 | F177: MMR011006027 | G177: ASIMMR011006027 | H177: GAD, Aug 2012 | K177: 11
A178: 11006 | B178: 110060070 | C178: Ka Lawt | D178: ကလော့ | E178: MMR011006 | F178: MMR011006007 | G178: ASIMMR011006007 | H178: GAD, Aug 2012 | K178: 11
A179: 11006 | B179: 110060220 | C179: Ka Nin Ka Mawt (Lamaing Sub-township) | D179: ကနင်ကမော့ | E179: MMR011006 | F179: MMR011006022 | G179: ASIMMR011006022 | H179: GAD, Aug 2012 | K179: 11
A180: 11006 | B180: 110060160 | C180: Kawt Dut (Lamaing Sub-township) | D180: ကော့ဒွတ် | E180: MMR011006 | F180: MMR011006016 | G180: ASIMMR011006016 | H180: GAD, Aug 2012 | K180: 11
A181: 11006 | B181: 110060260 | C181: Kawt Hlaing (Khawzar Sub-township) | D181: ကော့လှိုင် | E181: MMR011006 | F181: MMR011006026 | G181: ASIMMR011006026 | H181: GAD, Aug 2012 | K181: 11
A182: 11006 | B182: 110060250 | C182: Koe Maing (Khawzar Sub-township) | D182: ကိုးမိုင် | E182: MMR011006 | F182: MMR011006025 | G182: ASIMMR011006025 | H182: GAD, Aug 2012 | K182: 11
A183: 11006 | B183: 110060170 | C183: Ku Lar Koke (Lamaing Sub-township) | D183: ကုလားကုတ် | E183: MMR011006 | F183: MMR011006017 | G183: ASIMMR011006017 | H183: GAD, Aug 2012 | K183: 11
A184: 11006 | B184: 110060080 | C184: Kyauk Mi Khaung | D184: ကျောက်မိကျောင်း | E184: MMR011006 | F184: MMR011006008 | G184: ASIMMR011006008 | H184: GAD, Aug 2012 | K184: 11
A185: 11006 | B185: 110060050 | C185: Kyaung Ywar | D185: ကျောင်းရွာ | E185: MMR011006 | F185: MMR011006005 | G185: ASIMMR011006005 | H185: GAD, Aug 2012 | K185: 11
A186: 11006 | B186: 110060300 | C186: Kyon Nye (Khawzar Sub-township) | D186: ကျုံညဲ | E186: MMR011006 | F186: MMR011006030 | G186: ASIMMR011006030 | H186: GAD, Aug 2012 | K186: 11
A187: 11006 | B187: 110060280 | C187: Ma Gyi (Khawzar Sub-township) | D187: မကျီး | E187: MMR011006 | F187: MMR011006028 | G187: ASIMMR011006028 | H187: GAD, Aug 2012 | K187: 11
... A378: 11010 | B378: 110100080 | C378: Zwe Ka Lar | D378: ဇွဲကလာ | E378: MMR011010 | F378: MMR011010008 | G378: ASIMMR011010008 | H378: GAD, Aug 2012 | K378: 11
A379: Sorted by TownshipID and VT ID

Sheet 5_Wards
A1: Township_ID | B1: Ward_ID | C1: Ward_Name_EN | D1: Ward_Name_MM | E1: Town_ID | H1: Ward_Pcode | I1: Town_Pcode | J1: TS_Pcode | K1: Town | L1: Ward_Pcode | M1: Source | N1: Remark | O1: SR_ID
A2: 11001 | B2: 110011011 | C2: Shwe Myaing Thi Ri Ward | D2: ရွှေမြိုင်သီရိရပ်ကွက် | E2: 110011 | F2: 01 | G2: 11001001 | H2: MMR011001701501 | I2: MMR011001701 | J2: MMR011001 | K2: Mawlamyine Town | L2: MMR011001701501 | M2: GAD, Aug 2012 | O2: 11
A3: 11001 | B3: 110011021 | C3: Kyaik Hpa Nei Ward | D3: ကျိုက်ဖနဲရပ်ကွက် | E3: 110011 | F3: 02 | G3: 11001002 | H3: MMR011001701502 | I3: MMR011001701 | J3: MMR011001 | K3: Mawlamyine Town | L3: MMR011001701502 | M3: GAD, Aug 2012 | O3: 11
A4: 11001 | B4: 110011031 | C4: Hlaing Shan Su Ward | D4: လှိုင်ရှမ်းစုရပ်ကွက် | E4: 110011 | F4: 03 | G4: 11001003 | H4: MMR011001701503 | I4: MMR011001701 | J4: MMR011001 | K4: Mawlamyine Town | L4: MMR011001701503 | M4: GAD, Aug 2012 | O4: 11
A5: 11001 | B5: 110011041 | C5: Auk Kyin Ward | D5: အောက်ကျင်းရပ်ကွက် | E5: 110011 | F5: 04 | G5: 11001004 | H5: MMR011001701504 | I5: MMR011001701 | J5: MMR011001 | K5: Mawlamyine Town | L5: MMR011001701504 | M5: GAD, Aug 2012 | O5: 11
A6: 11001 | B6: 110011051 | C6: Mandalay Ward | D6: မန္တလေးရပ်ကွက် | E6: 110011 | F6: 05 | G6: 11001005 | H6: MMR011001701505 | I6: MMR011001701 | J6: MMR011001 | K6: Mawlamyine Town | L6: MMR011001701505 | M6: GAD, Aug 2012 | O6: 11
A7: 11001 | B7: 110011061 | C7: Hpet Tan Ward | D7: ဖက်တန်းရပ်ကွက် | E7: 110011 | F7: 06 | G7: 11001006 | H7: MMR011001701506 | I7: MMR011001701 | J7: MMR011001 | K7: Mawlamyine Town | L7: MMR011001701506 | M7: GAD, Aug 2012 | O7: 11
A8: 11001 | B8: 110011071 | C8: Shwe (South) Ward | D8: ရွှေတောင်ရပ်ကွက် | E8: 110011 | F8: 07 | G8: 11001007 | H8: MMR011001701507 | I8: MMR011001701 | J8: MMR011001 | K8: Mawlamyine Town | L8: MMR011001701507 | M8: GAD, Aug 2012 | O8: 11
A9: 11001 | B9: 110011081 | C9: Sit Ke Kone Ward | D9: စစ်ကဲကုန်းရပ်ကွက် | E9: 110011 | F9: 08 | G9: 11001008 | H9: MMR011001701508 | I9: MMR011001701 | J9: MMR011001 | K9: Mawlamyine Town | L9: MMR011001701508 | M9: GAD, Aug 2012 | O9: 11
A10: 11001 | B10: 110011091 | C10: Ma Yan Kone Ward | D10: မရမ်းကုန်းရပ်ကွက် | E10: 110011 | F10: 09 | G10: 11001009 | H10: MMR011001701509 | I10: MMR011001701 | J10: MMR011001 | K10: Mawlamyine Town | L10: MMR011001701509 | M10: GAD, Aug 2012 | O10: 11
A11: 11001 | B11: 110011101 | C11: Pan Be Dan Ward | D11: ပန်းဘဲတန်းရပ်ကွက် | E11: 110011 | F11: 10 | G11: 11001010 | H11: MMR011001701510 | I11: MMR011001701 | J11: MMR011001 | K11: Mawlamyine Town | L11: MMR011001701510 | M11: GAD, Aug 2012 | O11: 11
A12: 11001 | B12: 110011111 | C12: Bo Kone Ward | D12: ဘိုကုန်းရပ်ကွက် | E12: 110011 | F12: 11 | G12: 11001011 | H12: MMR011001701511 | I12: MMR011001701 | J12: MMR011001 | K12: Mawlamyine Town | L12: MMR011001701511 | M12: GAD, Aug 2012 | O12: 11
A13: 11001 | B13: 110011121 | C13: Maung Ngan Ward | D13: မောင်ငံရပ်ကွက် | E13: 110011 | F13: 12 | G13: 11001012 | H13: MMR011001701512 | I13: MMR011001701 | J13: MMR011001 | K13: Mawlamyine Town | L13: MMR011001701512 | M13: GAD, Aug 2012 | O13: 11
... A23: 11001 | B23: 110011221 | C23: Zay Yar Myaing Ward | D23: ဇေယျာမြိုင်ရပ်ကွက် | E23: 110011 | F23: 22 | G23: 11001022 | H23: MMR011001701522 | I23: MMR011001701 | J23: MMR011001 | K23: Mawlamyine Town | L23: MMR011001701522 | M23: GAD, Aug 2012 | O23: 11
A24: 11001 | B24: 110011231 | C24: Kyauk Tan Ward | D24: ကျောက်တန်းရပ်ကွက် | E24: 110011 | F24: 23 | G24: 11001023 | H24: MMR011001701523 | I24: MMR011001701 | J24: MMR011001 | K24: Mawlamyine Town | L24: MMR011001701523 | M24: GAD, Aug 2012 | N24: New Ward changed from VT, GAD 2012 | O24: 11
A25: 11001 | B25: 110011241 | C25: San Gyi Ward | D25: စမ်းကြီးရပ်ကွက် | E25: 110011 | F25: 24 | G25: 11001024 | H25: MMR011001701524 | I25: MMR011001701 | J25: MMR011001 | K25: Mawlamyine Town | L25: MMR011001701524 | M25: GAD, Aug 2012 | N25: New Ward changed from VT, GAD 2012 | O25: 11
A26: 11001 | B26: 110011251 | C26: Gway Kone Ward | D26: ဂွေးကုန်းရပ်ကွက် | E26: 110011 | F26: 25 | G26: 11001025 | H26: MMR011001701525 | I26: MMR011001701 | J26: MMR011001 | K26: Mawlamyine Town | L26: MMR011001701525 | M26: GAD, Aug 2012 | N26: New Ward changed from VT, GAD 2012 | O26: 11
A27: 11001 | B27: 110011261 | C27: Naung Kha Ri Ward | D27: နောင်ခရိရပ်ကွက် | E27: 110011 | F27: 26 | G27: 11001026 | H27: MMR011001701526 | I27: MMR011001701 | J27: MMR011001 | K27: Mawlamyine Town | L27: MMR011001701526 | M27: GAD, Aug 2012 | N27: New Ward changed from VT, GAD 2012 | O27: 11
A28: 11001 | B28: 110011271 | C28: Ngan Tay Ward | D28: ငန်းတေးရပ်ကွက် | E28: 110011 | F28: 27 | G28: 11001027 | H28: MMR011001701527 | I28: MMR011001701 | J28: MMR011001 | K28: Mawlamyine Town | L28: MMR011001701527 | M28: GAD, Aug 2012 | N28: New Ward changed from VT, GAD 2012 | O28: 11
A29: 11001 | B29: 110011281 | C29: Chauk Maing Kywe Chan Kone Ward | D29: ခြောက်မိုင်ကျွဲခြံကုန်းရပ်ကွက် | E29: 110011 | F29: 28 | G29: 11001028 | H29: MMR011001701528 | I29: MMR011001701 | J29: MMR011001 | K29: Mawlamyine Town | L29: MMR011001701528 | M29: GAD, Aug 2012 | N29: New Ward changed from VT, GAD 2012 | O29: 11
A30: 11002 | B30: 110021011 | C30: Shin Saw Pu Ward | D30: ရှင်စောပုရပ်ကွက် | E30: 110021 | F30: 01 | G30: 11002001 | H30: MMR011002701501 | I30: MMR011002701 | J30: MMR011002 | K30: Kyaikmaraw Town | L30: MMR011002701501 | M30: GAD, Aug 2012 | O30: 11
A31: 11002 | B31: 110021021 | C31: Yan Myo Aung Ward | D31: ရန်မျိုးအောင်ရပ်ကွက် | E31: 110021 | F31: 02 | G31: 11002002 | H31: MMR011002701502 | I31: MMR011002701 | J31: MMR011002 | K31: Kyaikmaraw Town | L31: MMR011002701502 | M31: GAD, Aug 2012 | O31: 11
A32: 11003 | B32: 110031011 | C32: Ah Nauk Ward | D32: အနောက်ရပ်ကွက် | E32: 110031 | F32: 01 | G32: 11003001 | H32: MMR011003701501 | I32: MMR011003701 | J32: MMR011003 | K32: Chaungzon Town | L32: MMR011003701501 | M32: GAD, Aug 2012 | O32: 11
A33: 11003 | B33: 110031021 | C33: Ah Shey Ward | D33: အရှေ့ရပ်ကွက် | E33: 110031 | F33: 02 | G33: 11003002 | H33: MMR011003701502 | I33: MMR011003701 | J33: MMR011003 | K33: Chaungzon Town | L33: MMR011003701502 | M33: GAD, Aug 2012 | O33: 11
A34: 11003 | B34: 110031031 | C34: Toe Cheit Ward | D34: တိုးချဲ့ရပ်ကွက် | E34: 110031 | F34: 03 | G34: 11003003 | H34: MMR011003701503 | I34: MMR011003701 | J34: MMR011003 | K34: Chaungzon Town | L34: MMR011003701503 | M34: GAD, Aug 2012 | O34: 11
A35: 11004 | B35: 110041011 | C35: Kyar Kan Ward | D35: ကြာကန်ရပ်ကွက် | E35: 110041 | F35: 01 | G35: 11004001 | H35: MMR011004701501 | I35: MMR011004701 | J35: MMR011004 | K35: Thanpyuzayat Town | L35: MMR011004701501 | M35: GAD, Aug 2012 | O35: 11
A36: 11004 | B36: 110041021 | C36: Aung Chan Thar Ward | D36: အောင်ချမ်းသာရပ်ကွက် | E36: 110041 | F36: 02 | G36: 11004002 | H36: MMR011004701502 | I36: MMR011004701 | J36: MMR011004 | K36: Thanpyuzayat Town | L36: MMR011004701502 | M36: GAD, Aug 2012 | O36: 11
A37: 11004 | B37: 110041031 | C37: Set Thit Ward | D37: စက်သစ်ရပ်ကွက် | E37: 110041 | F37: 03 | G37: 11004003 | H37: MMR011004701503 | I37: MMR011004701 | J37: MMR011004 | K37: Thanpyuzayat Town | L37: MMR011004701503 | M37: GAD, Aug 2012 | O37: 11
A38: 11004 | B38: 110041041 | C38: Aung Min Ga Lar Ward | D38: အောင်မင်္ဂလာရပ်ကွက် | E38: 110041 | F38: 04 | G38: 11004004 | H38: MMR011004701504 | I38: MMR011004701 | J38: MMR011004 | K38: Thanpyuzayat Town | L38: MMR011004701504 | M38: GAD, Aug 2012 | O38: 11
A39: 11004 | B39: 110041051 | C39: Han Thar Wa Di Ward | D39: ဟံသာဝတီရပ်ကွက် | E39: 110041 | F39: 05 | G39: 11004005 | H39: MMR011004701505 | I39: MMR011004701 | J39: MMR011004 | K39: Thanpyuzayat Town | L39: MMR011004701505 | M39: GAD, Aug 2012 | O39: 11
A40: 11004 | B40: 110041061 | C40: Aung Zay Ya Ward | D40: အောင်ဇေယျရပ်ကွက် | E40: 110041 | F40: 06 | G40: 11004006 | H40: MMR011004701506 | I40: MMR011004701 | J40: MMR011004 | K40: Thanpyuzayat Town | L40: MMR011004701506 | M40: GAD, Aug 2012 | O40: 11
A41: 11004 | B41: 110041071 | C41: Kyaung Paing Ward | D41: ကျောင်းပိုင်းရပ်ကွက် | E41: 110041 | F41: 07 | G41: 11004007 | H41: MMR011004701507 | I41: MMR011004701 | J41: MMR011004 | K41: Thanpyuzayat Town | L41: MMR011004701507 | M41: GAD, Aug 2012 | O41: 11
... A87: 11010 | B87: 110101051 | C87: Bo Tay Za Ward | D87: ဗိုလ်တေဇရပ်ကွက် | E87: 110101 | F87: 05 | G87: 11010005 | H87: MMR011010701505 | I87: MMR011010701 | J87: MMR011010 | K87: Bilin Town | L87: MMR011010701505 | M87: GAD, Aug 2012 | O87: 11
A90: Sorted by TownshipID and Ward ID

Sheet Ward_Names_TS
A1: Township_ID | B1: Town_ID | C1: Ward_ID | D1: Ward_Name_EN | E1: Ward_Name_MM | F1: Ward_Name | I1: Ward_Pcode | J1: Town_Pcode | K1: TS_Pcode | L1: Town | M1: Ward_Pcode | N1: Source | O1: Remark | P1: SR_ID
A2: 11001 | B2: 110011 | C2: 110011041 | D2: Auk Kyin Ward | E2: အောက်ကျင်းရပ်ကွက် | F2: Auk Kyin Ward - 110011041 | G2: 04 | H2: 11001004 | I2: MMR011001701504 | J2: MMR011001701 | K2: MMR011001 | L2: Mawlamyine Town | M2: MMR011001701504 | N2: GAD, Aug 2012 | P2: 11
A3: 11001 | B3: 110011 | C3: 110011111 | D3: Bo Kone Ward | E3: ဘိုကုန်းရပ်ကွက် | F3: Bo Kone Ward - 110011111 | G3: 11 | H3: 11001011 | I3: MMR011001701511 | J3: MMR011001701 | K3: MMR011001 | L3: Mawlamyine Town | M3: MMR011001701511 | N3: GAD, Aug 2012 | P3: 11
A4: 11001 | B4: 110011 | C4: 110011281 | D4: Chauk Maing Kywe Chan Kone Ward | E4: ခြောက်မိုင်ကျွဲခြံကုန်းရပ်ကွက် | F4: Chauk Maing Kywe Chan Kone Ward - 110011281 | G4: 28 | H4: 11001028 | I4: MMR011001701528 | J4: MMR011001701 | K4: MMR011001 | L4: Mawlamyine Town | M4: MMR011001701528 | N4: GAD, Aug 2012 | O4: New Ward changed from VT, GAD 2012 | P4: 11
A5: 11001 | B5: 110011 | C5: 110011251 | D5: Gway Kone Ward | E5: ဂွေးကုန်းရပ်ကွက် | F5: Gway Kone Ward - 110011251 | G5: 25 | H5: 11001025 | I5: MMR011001701525 | J5: MMR011001701 | K5: MMR011001 | L5: Mawlamyine Town | M5: MMR011001701525 | N5: GAD, Aug 2012 | O5: New Ward changed from VT, GAD 2012 | P5: 11
A6: 11001 | B6: 110011 | C6: 110011031 | D6: Hlaing Shan Su Ward | E6: လှိုင်ရှမ်းစုရပ်ကွက် | F6: Hlaing Shan Su Ward - 110011031 | G6: 03 | H6: 11001003 | I6: MMR011001701503 | J6: MMR011001701 | K6: MMR011001 | L6: Mawlamyine Town | M6: MMR011001701503 | N6: GAD, Aug 2012 | P6: 11
A7: 11001 | B7: 110011 | C7: 110011061 | D7: Hpet Tan Ward | E7: ဖက်တန်းရပ်ကွက် | F7: Hpet Tan Ward - 110011061 | G7: 06 | H7: 11001006 | I7: MMR011001701506 | J7: MMR011001701 | K7: MMR011001 | L7: Mawlamyine Town | M7: MMR011001701506 | N7: GAD, Aug 2012 | P7: 11
A8: 11001 | B8: 110011 | C8: 110011131 | D8: Kwin Yat Ward | E8: ကွင်းရပ်ရပ်ကွက် | F8: Kwin Yat Ward - 110011131 | G8: 13 | H8: 11001013 | I8: MMR011001701513 | J8: MMR011001701 | K8: MMR011001 | L8: Mawlamyine Town | M8: MMR011001701513 | N8: GAD, Aug 2012 | P8: 11
A9: 11001 | B9: 110011 | C9: 110011021 | D9: Kyaik Hpa Nei Ward | E9: ကျိုက်ဖနဲရပ်ကွက် | F9: Kyaik Hpa Nei Ward - 110011021 | G9: 02 | H9: 11001002 | I9: MMR011001701502 | J9: MMR011001701 | K9: MMR011001 | L9: Mawlamyine Town | M9: MMR011001701502 | N9: GAD, Aug 2012 | P9: 11
A10: 11001 | B10: 110011 | C10: 110011231 | D10: Kyauk Tan Ward | E10: ကျောက်တန်းရပ်ကွက် | F10: Kyauk Tan Ward - 110011231 | G10: 23 | H10: 11001023 | I10: MMR011001701523 | J10: MMR011001701 | K10: MMR011001 | L10: Mawlamyine Town | M10: MMR011001701523 | N10: GAD, Aug 2012 | O10: New Ward changed from VT, GAD 2012 | P10: 11
A11: 11001 | B11: 110011 | C11: 110011091 | D11: Ma Yan Kone Ward | E11: မရမ်းကုန်းရပ်ကွက် | F11: Ma Yan Kone Ward - 110011091 | G11: 09 | H11: 11001009 | I11: MMR011001701509 | J11: MMR011001701 | K11: MMR011001 | L11: Mawlamyine Town | M11: MMR011001701509 | N11: GAD, Aug 2012 | P11: 11
A12: 11001 | B12: 110011 | C12: 110011051 | D12: Mandalay Ward | E12: မန္တလေးရပ်ကွက် | F12: Mandalay Ward - 110011051 | G12: 05 | H12: 11001005 | I12: MMR011001701505 | J12: MMR011001701 | K12: MMR011001 | L12: Mawlamyine Town | M12: MMR011001701505 | N12: GAD, Aug 2012 | P12: 11
A13: 11001 | B13: 110011 | C13: 110011121 | D13: Maung Ngan Ward | E13: မောင်ငံရပ်ကွက် | F13: Maung Ngan Ward - 110011121 | G13: 12 | H13: 11001012 | I13: MMR011001701512 | J13: MMR011001701 | K13: MMR011001 | L13: Mawlamyine Town | M13: MMR011001701512 | N13: GAD, Aug 2012 | P13: 11
A14: 11001 | B14: 110011 | C14: 110011171 | D14: Mu Pon Ward | E14: မုပွန်ရပ်ကွက် | F14: Mu Pon Ward - 110011171 | G14: 17 | H14: 11001017 | I14: MMR011001701517 | J14: MMR011001701 | K14: MMR011001 | L14: Mawlamyine Town | M14: MMR011001701517 | N14: GAD, Aug 2012 | P14: 11
A15: 11001 | B15: 110011 | C15: 110011211 | D15: Myaing Thar Yar Ward | E15: မြိုင်သာယာရပ်ကွက် | F15: Myaing Thar Yar Ward - 110011211 | G15: 21 | H15: 11001021 | I15: MMR011001701521 | J15: MMR011001701 | K15: MMR011001 | L15: Mawlamyine Town | M15: MMR011001701521 | N15: GAD, Aug 2012 | P15: 11
A16: 11001 | B16: 110011 | C16: 110011141 | D16: Myay Ni Kone Ward | E16: မြေနီကုန်းရပ်ကွက် | F16: Myay Ni Kone Ward - 110011141 | G16: 14 | H16: 11001014 | I16: MMR011001701514 | J16: MMR011001701 | K16: MMR011001 | L16: Mawlamyine Town | M16: MMR011001701514 | N16: GAD, Aug 2012 | P16: 11
A17: 11001 | B17: 110011 | C17: 110011261 | D17: Naung Kha Ri Ward | E17: နောင်ခရိရပ်ကွက် | F17: Naung Kha Ri Ward - 110011261 | G17: 26 | H17: 11001026 | I17: MMR011001701526 | J17: MMR011001701 | K17: MMR011001 | L17: Mawlamyine Town | M17: MMR011001701526 | N17: GAD, Aug 2012 | O17: New Ward changed from VT, GAD 2012 | P17: 11
A18: 11001 | B18: 110011 | C18: 110011271 | D18: Ngan Tay Ward | E18: ငန်းတေးရပ်ကွက် | F18: Ngan Tay Ward - 110011271 | G18: 27 | H18: 11001027 | I18: MMR011001701527 | J18: MMR011001701 | K18: MMR011001 | L18: Mawlamyine Town | M18: MMR011001701527 | N18: GAD, Aug 2012 | O18: New Ward changed from VT, GAD 2012 | P18: 11
A19: 11001 | B19: 110011 | C19: 110011101 | D19: Pan Be Dan Ward | E19: ပန်းဘဲတန်းရပ်ကွက် | F19: Pan Be Dan Ward - 110011101 | G19: 10 | H19: 11001010 | I19: MMR011001701510 | J19: MMR011001701 | K19: MMR011001 | L19: Mawlamyine Town | M19: MMR011001701510 | N19: GAD, Aug 2012 | P19: 11
A20: 11001 | B20: 110011 | C20: 110011241 | D20: San Gyi Ward | E20: စမ်းကြီးရပ်ကွက် | F20: San Gyi Ward - 110011241 | G20: 24 | H20: 11001024 | I20: MMR011001701524 | J20: MMR011001701 | K20: MMR011001 | L20: Mawlamyine Town | M20: MMR011001701524 | N20: GAD, Aug 2012 | O20: New Ward changed from VT, GAD 2012 | P20: 11
A21: 11001 | B21: 110011 | C21: 110011071 | D21: Shwe (South) Ward | E21: ရွှေတောင်ရပ်ကွက် | F21: Shwe (South) Ward - 110011071 | G21: 07 | H21: 11001007 | I21: MMR011001701507 | J21: MMR011001701 | K21: MMR011001 | L21: Mawlamyine Town | M21: MMR011001701507 | N21: GAD, Aug 2012 | P21: 11
A22: 11001 | B22: 110011 | C22: 110011011 | D22: Shwe Myaing Thi Ri Ward | E22: ရွှေမြိုင်သီရိရပ်ကွက် | F22: Shwe Myaing Thi Ri Ward - 110011011 | G22: 01 | H22: 11001001 | I22: MMR011001701501 | J22: MMR011001701 | K22: MMR011001 | L22: Mawlamyine Town | M22: MMR011001701501 | N22: GAD, Aug 2012 | P22: 11
A23: 11001 | B23: 110011 | C23: 110011081 | D23: Sit Ke Kone Ward | E23: စစ်ကဲကုန်းရပ်ကွက် | F23: Sit Ke Kone Ward - 110011081 | G23: 08 | H23: 11001008 | I23: MMR011001701508 | J23: MMR011001701 | K23: MMR011001 | L23: Mawlamyine Town | M23: MMR011001701508 | N23: GAD, Aug 2012 | P23: 11
A24: 11001 | B24: 110011 | C24: 110011191 | D24: Thar Yar Aye Ward | E24: သာယာအေးရပ်ကွက် | F24: Thar Yar Aye Ward - 110011191 | G24: 19 | H24: 11001019 | I24: MMR011001701519 | J24: MMR011001701 | K24: MMR011001 | L24: Mawlamyine Town | M24: MMR011001701519 | N24: GAD, Aug 2012 | P24: 11
A25: 11001 | B25: 110011 | C25: 110011201 | D25: Thi Ri Min Ga Lar Ward | E25: သီရိမင်္ဂလာရပ်ကွက် | F25: Thi Ri Min Ga Lar Ward - 110011201 | G25: 20 | H25: 11001020 | I25: MMR011001701520 | J25: MMR011001701 | K25: MMR011001 | L25: Mawlamyine Town | M25: MMR011001701520 | N25: GAD, Aug 2012 | P25: 11
A26: 11001 | B26: 110011 | C26: 110011161 | D26: Thi Ri Myaing Ward | E26: သီရိမြိုင်ရပ်ကွက် | F26: Thi Ri Myaing Ward - 110011161 | G26: 16 | H26: 11001016 | I26: MMR011001701516 | J26: MMR011001701 | K26: MMR011001 | L26: Mawlamyine Town | M26: MMR011001701516 | N26: GAD, Aug 2012 | P26: 11
A27: 11001 | B27: 110011 | C27: 110011151 | D27: Zay Cho Ward | E27: ဈေးချိုရပ်ကွက် | F27: Zay Cho Ward - 110011151 | G27: 15 | H27: 11001015 | I27: MMR011001701515 | J27: MMR011001701 | K27: MMR011001 | L27: Mawlamyine Town | M27: MMR011001701515 | N27: GAD, Aug 2012 | P27: 11
A28: 11001 | B28: 110011 | C28: 110011221 | D28: Zay Yar Myaing Ward | E28: ဇေယျာမြိုင်ရပ်ကွက် | F28: Zay Yar Myaing Ward - 110011221 | G28: 22 | H28: 11001022 | I28: MMR011001701522 | J28: MMR011001701 | K28: MMR011001 | L28: Mawlamyine Town | M28: MMR011001701522 | N28: GAD, Aug 2012 | P28: 11
A29: 11001 | B29: 110011 | C29: 110011181 | D29: Zay Yar Thi Ri Ward | E29: ဇေယျာသီရိရပ်ကွက် | F29: Zay Yar Thi Ri Ward - 110011181 | G29: 18 | H29: 11001018 | I29: MMR011001701518 | J29: MMR011001701 | K29: MMR011001 | L29: Mawlamyine Town | M29: MMR011001701518 | N29: GAD, Aug 2012 | P29: 11
A30: 11002 | B30: 110021 | C30: 110021011 | D30: Shin Saw Pu Ward | E30: ရှင်စောပုရပ်ကွက် | F30: Shin Saw Pu Ward - 110021011 | G30: 01 | H30: 11002001 | I30: MMR011002701501 | J30: MMR011002701 | K30: MMR011002 | L30: Kyaikmaraw Town | M30: MMR011002701501 | N30: GAD, Aug 2012 | P30: 11
A31: 11002 | B31: 110021 | C31: 110021021 | D31: Yan Myo Aung Ward | E31: ရန်မျိုးအောင်ရပ်ကွက် | F31: Yan Myo Aung Ward - 110021021 | G31: 02 | H31: 11002002 | I31: MMR011002701502 | J31: MMR011002701 | K31: MMR011002 | L31: Kyaikmaraw Town | M31: MMR011002701502 | N31: GAD, Aug 2012 | P31: 11
A32: 11003 | B32: 110031 | C32: 110031011 | D32: Ah Nauk Ward | E32: အနောက်ရပ်ကွက် | F32: Ah Nauk Ward - 110031011 | G32: 01 | H32: 11003001 | I32: MMR011003701501 | J32: MMR011003701 | K32: MMR011003 | L32: Chaungzon Town | M32: MMR011003701501 | N32: GAD, Aug 2012 | P32: 11
... A87: 11010 | B87: 110101 | C87: 110101011 | D87: Sa Yar San Ward | E87: ဆရာစံရပ်ကွက် | F87: Sa Yar San Ward - 110101011 | G87: 01 | H87: 11010001 | I87: MMR011010701501 | J87: MMR011010701 | K87: MMR011010 | L87: Bilin Town | M87: MMR011010701501 | N87: GAD, Aug 2012 | P87: 11
A90: Sorted by TownshipID and Ward Name

Sheet Village_Names_TS
A1: Township_ID | B1: VT_ID | C1: Village_ID | D1: Village_EN | E1: Village_MM | F1: Village_Name | G1: SR_ID
A2: 11001 | B2: 110010180 | C2: 194969 | D2: Hpar Auk | E2: ဖားအောက် | F2: Hpar Auk - 194969 | G2: 11
A3: 11001 | B3: 110010070 | C3: 194940 | D3: Hpe Htaw | E3: ဖဲထော် | F3: Hpe Htaw - 194940 | G3: 11
A4: 11001 | B4: 110010010 | C4: 194925 | D4: Ka Toe | E4: ကတိုး | F4: Ka Toe - 194925 | G4: 11
A5: 11001 | B5: 110010070 | C5: 194939 | D5: Kawt Hlar | E5: ကော့လှာ | F5: Kawt Hlar - 194939 | G5: 11
A6: 11001 | B6: 110010060 | C6: 194934 | D6: Kawt Hnat | E6: ကော့နှပ် | F6: Kawt Hnat - 194934 | G6: 11
A7: 11001 | B7: 110010170 | C7: 194966 | D7: Kawt Kha Mei | E7: ကော့ခမယ် | F7: Kawt Kha Mei - 194966 | G7: 11
A8: 11001 | B8: 110010140 | C8: 194957 | D8: Kawt Kha Ni | E8: ကော့ခနိ | F8: Kawt Kha Ni - 194957 | G8: 11
A9: 11001 | B9: 110010170 | C9: 194967 | D9: Kawt Kha Po | E9: ကော့ခပို | F9: Kawt Kha Po - 194967 | G9: 11
A10: 11001 | B10: 110010080 | C10: 194941 | D10: Kawt Pauk | E10: ကော့ပေါက် | F10: Kawt Pauk - 194941 | G10: 11
A11: 11001 | B11: 110010050 | C11: 194931 | D11: Kawt Tun | E11: ကော့တွန် | F11: Kawt Tun - 194931 | G11: 11
A12: 11001 | B12: 110010050 | C12: 194932 | D12: Kawt Tun Kwin Paing | E12: ကော့တွန်ကွင်းပိုင်း | F12: Kawt Tun Kwin Paing - 194932 | G12: 11
A13: 11001 | B13: 110010020 | C13: 194926 | D13: Kawt Wein Ywar Ma | E13: ကော့ဝိန်ရွာမ | F13: Kawt Wein Ywar Ma - 194926 | G13: 11
... A1183: 11010 | B1183: 110100080 | C1183: 195919 | D1183: Zwe Ka Lar | E1183: ဇွဲကလာ | F1183: Zwe Ka Lar - 195919 | G1183: 11
A1186: Sorted by TownshipID and Village Name

Sheet Village_Names_VT
A1: Township_ID | B1: VT_ID | C1: Village_ID | D1: Village_EN | E1: Village_MM | F1: Village_Name | G1: SR_ID
A2: 11001 | B2: 110010010 | C2: 194925 | D2: Ka Toe | E2: ကတိုး | F2: Ka Toe - 194925 | G2: 11
A3: 11001 | B3: 110010020 | C3: 194926 | D3: Kawt Wein Ywar Ma | E3: ကော့ဝိန်ရွာမ | F3: Kawt Wein Ywar Ma - 194926 | G3: 11
A4: 11001 | B4: 110010020 | C4: 194927 | D4: Kawt Wein Ywar Thit | E4: ကော့ဝိန်ရွာသစ် | F4: Kawt Wein Ywar Thit - 194927 | G4: 11
A5: 11001 | B5: 110010050 | C5: 194931 | D5: Kawt Tun | E5: ကော့တွန် | F5: Kawt Tun - 194931 | G5: 11
A6: 11001 | B6: 110010050 | C6: 194932 | D6: Kawt Tun Kwin Paing | E6: ကော့တွန်ကွင်းပိုင်း | F6: Kawt Tun Kwin Paing - 194932 | G6: 11
A7: 11001 | B7: 110010050 | C7: 194933 | D7: Zaw Ya Kyun | E7: ဇော်ရကျွန်း | F7: Zaw Ya Kyun - 194933 | G7: 11
A8: 11001 | B8: 110010060 | C8: 194934 | D8: Kawt Hnat | E8: ကော့နှပ် | F8: Kawt Hnat - 194934 | G8: 11
A9: 11001 | B9: 110010060 | C9: 194935 | D9: Kun Tar | E9: ကွမ်တာ | F9: Kun Tar - 194935 | G9: 11
A10: 11001 | B10: 110010060 | C10: 194936 | D10: Than Ka Paing | E10: သံကပိုင်း | F10: Than Ka Paing - 194936 | G10: 11
A11: 11001 | B11: 110010070 | C11: 194940 | D11: Hpe Htaw | E11: ဖဲထော် | F11: Hpe Htaw - 194940 | G11: 11
A12: 11001 | B12: 110010070 | C12: 194939 | D12: Kawt Hlar | E12: ကော့လှာ | F12: Kawt Hlar - 194939 | G12: 11
A13: 11001 | B13: 110010080 | C13: 194941 | D13: Kawt Pauk | E13: ကော့ပေါက် | F13: Kawt Pauk - 194941 | G13: 11
... A1183: 11010 | B1183: 110100500 | C1183: 196121 | D1183: Thet Kei Kyin | E1183: သက်ကယ်ကျင်း | F1183: Thet Kei Kyin - 196121 | G1183: 11
A1186: Sorted by TownshipID, Village Tract ID and Village Name

Sheet 7_Villages
A1: Township_ID | B1: VT_ID | C1: Village_ID | D1: Village_EN | E1: Village_MM | F1: VT_Pcode | G1: Village_Tract | H1: Village_Alias_EN | I1: Village_Alias_MM | J1: Longitude | K1: Latitude | L1: Source | M1: Remark | N1: Old_Village_Pcode | O1: SR_PCode | P1: SR_ID
A2: 11001 | B2: 110010010 | C2: 194925 | D2: Ka Toe | E2: ကတိုး | F2: MMR011001001 | G2: Ka Toe | J2: 97.66 | K2: 16.58 | L2: GAD, Aug 2012 | P2: 11
A3: 11001 | B3: 110010020 | C3: 194926 | D3: Kawt Wein Ywar Ma | E3: ကော့ဝိန်ရွာမ | F3: MMR011001002 | G3: Kawt Wein | J3: 97.63 | K3: 16.56 | L3: GAD, Aug 2012 | P3: 11
A4: 11001 | B4: 110010020 | C4: 194927 | D4: Kawt Wein Ywar Thit | E4: ကော့ဝိန်ရွာသစ် | F4: MMR011001002 | G4: Kawt Wein | J4: 97.64 | K4: 16.57 | L4: GAD, Aug 2012 | P4: 11
A5: 11001 | B5: 110010050 | C5: 194931 | D5: Kawt Tun | E5: ကော့တွန် | F5: MMR011001005 | G5: Kawt Tun | J5: 97.65 | K5: 16.55 | L5: GAD, Aug 2012 | P5: 11
A6: 11001 | B6: 110010050 | C6: 194932 | D6: Kawt Tun Kwin Paing | E6: ကော့တွန်ကွင်းပိုင်း | F6: MMR011001005 | G6: Kawt Tun | J6: 97.65 | K6: 16.56 | L6: GAD, Aug 2012 | P6: 11
A7: 11001 | B7: 110010050 | C7: 194933 | D7: Zaw Ya Kyun | E7: ဇော်ရကျွန်း | F7: MMR011001005 | G7: Kawt Tun | L7: GAD, Aug 2012 | P7: 11
A8: 11001 | B8: 110010060 | C8: 194934 | D8: Kawt Hnat | E8: ကော့နှပ် | F8: MMR011001006 | G8: Kawt Hnat | J8: 97.66 | K8: 16.58 | L8: GAD, Aug 2012 | P8: 11
A9: 11001 | B9: 110010060 | C9: 194935 | D9: Kun Tar | E9: ကွမ်တာ | F9: MMR011001006 | G9: Kawt Hnat | L9: GAD, Aug 2012 | P9: 11
A10: 11001 | B10: 110010060 | C10: 194936 | D10: Than Ka Paing | E10: သံကပိုင်း | F10: MMR011001006 | G10: Kawt Hnat | L10: GAD, Aug 2012 | P10: 11
A11: 11001 | B11: 110010070 | C11: 194939 | D11: Kawt Hlar | E11: ကော့လှာ | F11: MMR011001007 | G11: Kawt Hlar | J11: 97.68 | K11: 16.57 | L11: GAD, Aug 2012 | P11: 11
A12: 11001 | B12: 110010070 | C12: 194940 | D12: Hpe Htaw | E12: ဖဲထော် | F12: MMR011001007 | G12: Kawt Hlar | J12: 97.68 | K12: 16.58 | L12: GAD, Aug 2012 | P12: 11
A13: 11001 | B13: 110010080 | C13: 194941 | D13: Kawt Pauk | E13: ကော့ပေါက် | F13: MMR011001008 | G13: Kawt Pauk | J13: 97.64 | K13: 16.55 | L13: GAD, Aug 2012 | P13: 11
A14: 11001 | B14: 110010080 | C14: 194942 | D14: Ma Yan | E14: မရမ်း | F14: MMR011001008 | G14: Kawt Pauk | L14: GAD, Aug 2012 | P14: 11
A15: 11001 | B15: 110010080 | C15: 194943 | D15: Ma Yan Kwin | E15: မရမ်းကွင်း | F15: MMR011001008 | G15: Kawt Pauk | L15: GAD, Aug 2012 | P15: 11
A16: 11001 | B16: 110010100 | C16: 194946 | D16: Min Ywar | E16: မင်းရွာ | F16: MMR011001010 | G16: Min Ywar | J16: 97.67 | K16: 16.47 | L16: GAD, Aug 2012 | P16: 11
A17: 11001 | B17: 110010100 | C17: 194947 | D17: Ywar Thin | E17: ရွာသင် | F17: MMR011001010 | G17: Min Ywar | J17: 97.68 | K17: 16.46 | L17: GAD, Aug 2012 | P17: 11
A18: 11001 | B18: 110010100 | C18: 194948 | D18: Put Ta Lu Kone | E18: ပွတ္တလူးကုန်း | F18: MMR011001010 | G18: Min Ywar | L18: GAD, Aug 2012 | P18: 11
A19: 11001 | B19: 110010110 | C19: 194949 | D19: Mu Yaung | E19: မုရောင်း | F19: MMR011001011 | G19: Mu Yaung | J19: 97.69 | K19: 16.44 | L19: GAD, Aug 2012 | P19: 11
A20: 11001 | B20: 110010110 | C20: 194950 | D20: Put Ta Lu Kone | E20: ပွတ္တလူးကုန်း | F20: MMR011001011 | G20: Mu Yaung | L20: GAD, Aug 2012 | P20: 11
A21: 11001 | B21: 110010110 | C21: 194951 | D21: Kyet Thun Kone | E21: ကြက်သွန်ကုန်း | F21: MMR011001011 | G21: Mu Yaung | L21: GAD, Aug 2012 | P21: 11
A22: 11001 | B22: 110010140 | C22: 194957 | D22: Kawt Kha Ni | E22: ကော့ခနိ | F22: MMR011001014 | G22: Kawt Kha Ni | J22: 97.64 | K22: 16.39 | L22: GAD, Aug 2012 | P22: 11
A23: 11001 | B23: 110010140 | C23: 194958 | D23: Kawt Ya | E23: ကော့ရ | F23: MMR011001014 | G23: Kawt Kha Ni | L23: GAD, Aug 2012 | P23: 11
A24: 11001 | B24: 110010160 | C24: 194962 | D24: Kyar Inn | E24: ကြာအင်း | F24: MMR011001016 | G24: Kyar Inn | J24: 97.67 | K24: 16.38 | L24: GAD, Aug 2012 | P24: 11
A25: 11001 | B25: 110010160 | C25: 194963 | D25: Kha Run | E25: ခရွန်း | F25: MMR011001016 | G25: Kyar Inn | L25: GAD, Aug 2012 | P25: 11
A26: 11001 | B26: 110010160 | C26: 194964 | D26: Zaw Kone | E26: ဇော်ကုန်း | F26: MMR011001016 | G26: Kyar Inn | L26: GAD, Aug 2012 | P26: 11
A27: 11001 | B27: 110010160 | C27: 194965 | D27: Shan Ywar | E27: ရှမ်းရွာ | F27: MMR011001016 | G27: Kyar Inn | L27: GAD, Aug 2012 | P27: 11
A28: 11001 | B28: 110010170 | C28: 194966 | D28: Kawt Kha Mei | E28: ကော့ခမယ် | F28: MMR011001017 | G28: Kawt Kha Mei | J28: 97.66 | K28: 16.38 | L28: GAD, Aug 2012 | P28: 11
A29: 11001 | B29: 110010170 | C29: 194967 | D29: Kawt Kha Po | E29: ကော့ခပို | F29: MMR011001017 | G29: Kawt Kha Mei | L29: GAD, Aug 2012 | P29: 11
A30: 11001 | B30: 110010170 | C30: 194968 | D30: Thu Gyi Kone | E30: သူကြီးကုန်း | F30: MMR011001017 | G30: Kawt Kha Mei | L30: GAD, Aug 2012 | P30: 11
A31: 11001 | B31: 110010180 | C31: 194969 | D31: Hpar Auk | E31: ဖားအောက် | F31: MMR011001018 | G31: Hpar Auk | J31: 97.66 | K31: 16.37 | L31: GAD, Aug 2012 | P31: 11
A32: 11001 | B32: 110010190 | C32: 194970 | D32: Yo Go (Ywar Haung) | E32: ရိုးဂိုး (ရွာဟောင်း) | F32: MMR011001019 | G32: Yo Go | J32: 97.67 | K32: 16.36 | L32: GAD, Aug 2012 | P32: 11
A33: 11001 | B33: 110010190 | C33: 194971 | D33: Yo Go (Ywar thit) | E33: ရိုးဂိုး (ရွာသစ်) | F33: MMR011001019 | G33: Yo Go | J33: 97.67 | K33: 16.36 | L33: GAD, Aug 2012 | P33: 11
A34: 11002 | B34: 110020010 | C34: 194972 | D34: An Ka Ye | E34: အံကရဲ | F34: MMR011002001 | G34: An Ka Ye | J34: 97.85 | K34: 16.41 | L34: GAD, Aug 2012 | N34: MMR011002001001 | P34: 11
A35: 11002 | B35: 110020010 | C35: 194973 | D35: Kat Ka Taung | E35: ကပ်ကတောင် | F35: MMR011002001 | G35: An Ka Ye | J35: 97.84 | K35: 16.43 | L35: GAD, Aug 2012 | N35: MMR011002001002 | P35: 11
A36: 11002 | B36: 110020010 | C36: 194974 | D36: Daung Kone | E36: ဒေါင်းကုန်း | F36: MMR011002001 | G36: An Ka Ye | J36: 97.86 | K36: 16.43 | L36: GAD, Aug 2012 | N36: MMR011002001003 | P36: 11
A37: 11002 | B37: 110020020 | C37: 194975 | D37: Ah Hta Yan | E37: အထရံ | F37: MMR011002002 | G37: Ah Hta Yan | L37: GAD, Aug 2012 | N37: MMR011002002001 | P37: 11
A38: 11002 | B38: 110020020 | C38: 194976 | D38: Paw Law Kone | E38: ပေါလောကုန်း | F38: MMR011002002 | G38: Ah Hta Yan | J38: 97.92 | K38: 16.22 | L38: GAD, Aug 2012 | N38: MMR011002002002 | P38: 11
A39: 11002 | B39: 110020020 | C39: 194977 | D39: Mee Thway Kone | E39: မီးသွေးကုန်း | F39: MMR011002002 | G39: Ah Hta Yan | J39: 97.91 | K39: 16.21 | L39: GAD, Aug 2012 | N39: MMR011002002003 | P39: 11
A40: 11002 | B40: 110020020 | C40: 194978 | D40: Kawt Tar | E40: ကော့တာ | F40: MMR011002002 | G40: Ah Hta Yan | L40: GAD, Aug 2012 | N40: MMR011002002004 | P40: 11
...

Sheet Clean_SchoolInfo
A1: School_ID | B1: VT_Ward_ID | C1: Village_ID | D1: School_Name | E1: Academic_Year_ID | F1: Latitude | G1: Longitude
A2: =CLEAN(Selected_School_ID) -> 11008018001 | B2: =Selected_Ward_VT_ID -> 110080180 | C2: =IFERROR(Selected_Village_ID,"") -> 195703 | D2: =CLEAN(Selected_School_Name) -> အ.ထ.က ရင်ငြိမ် | E2: =AcademicYear_ID -> 2014 | F2: ='SA-1'!$L$31 -> 0 | G2: ='SA-1'!$L$35 -> 0
A4: =LEN(A2) -> 11 | B4: =LEN(B2) -> 9 | C4: =LEN(C2) -> 6 | D4: =LEN(D2) -> 14 | E4: =LEN(E2) -> 4

Sheet Clean_School_AYInfo
A1: School_AY_Info_ID | B1: School_ID | C1: Academic_Year_ID
A2: ="30" & AcademicYear_ID& "" & Selected_School_ID -> 30201411008018001 | B2: =CLEAN(Selected_School_ID) -> 11008018001 | C2: =AcademicYear_ID -> 2014
A5: =LEN(SchoolAY_Info_ID) -> 17 | B5: =LEN(B2) -> 11 | C5: =LEN(C2) -> 4

Sheet Form_Setup
C1: Welcome to the Township Education Management System. In order to use this program, click 'Options...' on the Message Bar and select 'Enable this content'. Alternatively, open the file with Macro Control from a Trusted Location.
A3: Township_ID | B3: TS_PCode | C3: NEMIS_TS_Index | D3: Township_EN | E3: Township_MM | F3: State / Region ID | G3: SR_PCode | H3: State_Region_EN | I3: State_Region_MM | J3: D_PCode | K3: District | L3: MYA_INFO_TS_ID | M3: Source | N3: Remark
A4: 11008 | B4: MMR011008 | C4: 180 | D4: Paung | E4: ပေါင် | F4: 11 | G4: MMR011 | H4: Mon | I4: မွန်ပြည်နယ် | J4: MMR011D002 | K4: Thaton | L4: ASIMMR011008 | M4: GAD, Aug 2012
B7: Academic Start Date | C7: Academic End Date | F7: IncomeTypeCode | G7: IncomeTypeName | I7: ExpenditureTypeCode | J7: ExpenditureTypeName
B8: 41426 | C8: 41727 | F8: 1 | G8: School Fees | I8: 1 | J8: Ordinary
F9: 2 | I9: 2 | J9: Lump Sum
F10: 3 | I10: 3
F11: 4 | I11: 4
F12: 5 | I12: 5
B14: Monitoring Learning Achievement (Grade 9, 10, 11) (Every half year test)
C15: Month Name | D15: Moth in Digits
B16: First-Half Year End Test | C16: September | D16: =INDEX(Month_List,MATCH($C16,Month_Name,0),1) -> 09
B17: Second-Half Year End Test | C17: February | D17: =INDEX(Month_List,MATCH($C17,Month_Name,0),1) -> 02
B20: Today Date | C20: 41727
B22: Current System Date | C22: =TODAY() -> 42072

Sheet SA-1
B1: The Republic of the Union of Myanmar
B2: Ministry of Education
B3: Township Education Management Information System
B4: SCHOOL INFORMATION (END OF FEBRUARY)
F6: Academic Year | G6: =AcademicYear_Name -> 2013-2014 | J6: Feb
D8: Township | E8: =Township_Name_EN -> Paung | J8: State / Region | K8: =StateRegion_Name_EN -> Mon
D9: TS_Myanmar | E9: =Township_Name_MM -> ပေါင် | J9: SR_Myanmar | K9: =StateRegion_Name_MM -> မွန်ပြည်နယ်
A11: 1 | B11: Location
A13: 2 | B13: Village Tract / Ward | H13: =IFERROR(IF(CLEAN(Selected_Urban_Rural)=CLEAN(1),INDEX('5_Wards'!B2:D87,MATCH(CLEAN(Selected_Ward_VT_ID),'5_Wards'!B2:B87,0),3),INDEX('6_Village_Tracts'!B2:D378,MATCH(CLEAN(Selected_Ward_VT_ID),'6_Village_Tracts'!B2:B378,0),3)),"") -> ရင်းငြိမ် (မြောက်)
A15: 3 | B15: Village | H15: =IFERROR(IF(CLEAN(Selected_Urban_Rural)=CLEAN(1),$A$1,INDEX('7_Villages'!C2:E1183,MATCH(VALUE(Selected_Village_ID),'7_Villages'!C2:C1183,0),3)),"") -> ရင်းငြိမ် (မြောက်)
A17: 4 | B17: School Suffix ID | D17: =IFERROR(CLEAN(Selected_Ward_VT_ID),"") -> 110080180 | F17: 01 | H17: School ID | I17: =IFERROR( CLEAN(Selected_Ward_VT_ID) & F17,"") -> 11008018001
B19: School Name | D19: အ.ထ.က ရင်ငြိမ်
A22: 5 | B22: School Level | C22: =SUM(PRODUCT(C25*1),PRODUCT(D25*2),PRODUCT(E25*3),PRODUCT(F25*4),PRODUCT(G25*5),PRODUCT(H25*6),PRODUCT(I25*7),PRODUCT(J25*8),PRODUCT(K25*9),PRODUCT(L25*10),PRODUCT(M25*11),PRODUCT(N25*12)) -> 1
B24: School Level | C24: SHS | D24: SMS | E24: SPS | F24: Br-High | G24: Br-Mid | H24: Br-Pri | I24: Af-High | J24: Af-Mid | K24: Af-Pri | L24: Post-Pri | M24: Monastic | N24: Community
C25: 1 | D25: 0 | E25: 0 | F25: 0 | G25: 0 | H25: 0 | I25: 0 | J25: 0 | K25: 0 | L25: 0 | M25: 0 | N25: 0
C27: Level exist | L27: GeoLocation
A29: 6 | B29: If your school is an affiliated or branch or post primary school, which main school is your school attached to? | L29: Latitude
C31: Main School Suffix ID | D31: =Township_ID -> 11008 | H31: Main School ID | I31: =Township_ID & E31 -> 11008
C33: Main school name | L33: Longitude
A35: 7 | B35: Shift of school | D35: One | E35: Two | F35: 8 | G35: School Board of Trustee | I35: Yes | J35: No
D36: 1 | I36: 1
A39: 9 | B39: Distance from TEO office | D39: 12 | E39: Mile
A41: 10 | B41: School land ownership | J41: If Govt
C42: Land Ownership | D42: Govt | E42: Monastery | F42: Private | G42: Faith | H42: Other | J42: Govt Land Type | K42: Garan | L42: Lana39 | M42: F-105
B43: =SUM(PRODUCT(D43,1),PRODUCT(E43,2),PRODUCT(F43,3),PRODUCT(G43,4),PRODUCT(H43,5)) -> 1 | D43: 1 | E43: 0 | F43: 0 | G43: 0 | H43: 0 | I43: =SUM(PRODUCT(K43,1),PRODUCT(L43,2),PRODUCT(M43,3)) -> 2 | K43: 0 | L43: 1 | M43: 0
A45: 11 | B45: Area of school compound | D45: Length | F45: feet | G45: Width | I45: feet | K45: In Area | L45: 9.84 | M45: Acre
A48: 12 | B48: School Facilities (Number)
C50: 4 | D50: Four seated Tables | F50: 41 | G50: =INDEX(Facility_List,MATCH(D50,Facility_Name,0),1) -> 1 | H50: 4 | I50: Four seated Chairs | K50: 41 | L50: =INDEX(Facility_List,MATCH(I50,Facility_Name,0),1) -> 2
C52: 3 | D52: Three seated Tables | F52: 218 | G52: =INDEX(Facility_List,MATCH(D52,Facility_Name,0),1) -> 3 | H52: 3 | I52: Three seated Chairs | K52: 218 | L52: =INDEX(Facility_List,MATCH(I52,Facility_Name,0),1) -> 4
C54: 2 | D54: Two seated Tables | G54: =INDEX(Facility_List,MATCH(D54,Facility_Name,0),1) -> 5 | H54: 2 | I54: Two seated Chairs | L54: =INDEX(Facility_List,MATCH(I54,Facility_Name,0),1) -> 6
C56: 1 | D56: One seated Tables | F56: 184 | G56: =INDEX(Facility_List,MATCH(D56,Facility_Name,0),1) -> 7 | H56: 1 | I56: One seated Chairs | K56: 184 | L56: =INDEX(Facility_List,MATCH(I56,Facility_Name,0),1) -> 8
D58: Tables (4 seated; low) | G58: =INDEX(Facility_List,MATCH(D58,Facility_Name,0),1) -> 9
D60: Teacher Tables | F60: 17 | G60: =INDEX(Facility_List,MATCH(D60,Facility_Name,0),1) -> 10 | I60: Teacher Chairs | K60: 17 | L60: =INDEX(Facility_List,MATCH(I60,Facility_Name,0),1) -> 11
D62: Black/White board | F62: 17 | G62: =INDEX(Facility_List,MATCH(D62,Facility_Name,0),1) -> 12 | I62: OHP/LCD | L62: =INDEX(Facility_List,MATCH(I62,Facility_Name,0),1) -> 13
D64: Total Computers | F64: 4 | G64: =INDEX(Facility_List,MATCH(D64,Facility_Name,0),1) -> 14 | I64: Usable Computers | K64: 1 | L64: =INDEX(Facility_List,MATCH(I64,Facility_Name,0),1) -> 15
D66: Total Printers | F66: 1 | G66: =INDEX(Facility_List,MATCH(D66,Facility_Name,0),1) -> 16 | I66: Usable Printers | K66: 1 | L66: =INDEX(Facility_List,MATCH(I66,Facility_Name,0),1) -> 17
D68: Total Type Writers | F68: 1 | G68: =INDEX(Facility_List,MATCH(D68,Facility_Name,0),1) -> 18 | I68: Usable Type Writers | K68: 0 | L68: =INDEX(Facility_List,MATCH(I68,Facility_Name,0),1) -> 19
D70: Total Radio Cassette | F70: 1 | G70: =INDEX(Facility_List,MATCH(D70,Facility_Name,0),1) -> 20 | I70: Usable Radio Cassette | K70: 1 | L70: =INDEX(Facility_List,MATCH(I70,Facility_Name,0),1) -> 21
D72: Total TV | F72: 3 | G72: =INDEX(Facility_List,MATCH(D72,Facility_Name,0),1) -> 22 | I72: Usable TV | K72: 3 | L72: =INDEX(Facility_List,MATCH(I72,Facility_Name,0),1) -> 23
D74: Total VCD | G74: =INDEX(Facility_List,MATCH(D74,Facility_Name,0),1) -> 24 | I74: Usable VCD | L74: =INDEX(Facility_List,MATCH(I74,Facility_Name,0),1) -> 25
...

Sheet Clean_SA_1 _Head
A1: SA_1_ID | B1: School_AY_Info_ID | C1: AcdemicMonth
A2: ="31" & C2 & AcademicYear_ID& "" & TSIndex_SchoolID -> 31022014180018001 | B2: =CLEAN(SchoolAY_Info_ID) -> 30201411008018001 | C2: 02
A5: =LEN($A$2) -> 17 | B5: =LEN($B$2) -> 17 | C5: =LEN($C$2) -> 2 | D5: =LEN($D$2) -> 0 | E5: =LEN($E$2) -> 0 | F5: =LEN($F$2) -> 0
E7: =8+11 -> 19

Sheet Clean_SA_1 SchoolDetailInfo
A1: SA_1_ID | B1: SchoolLevel_ID | C1: SchoolLevelExist_ID | D1: MainSchool_ID | E1: ShiftOfSchool_ID | F1: BoardOfTrustee_YN
A2: =SA_1_ID -> 31022014180018001 | B2: =Selected_School_Level -> 1 | C2: =Selected_School_Level_Exist -> 6 | D2: =IFERROR(Selected_School_ID,"") -> 11008018001 | E2: =Selected_SchoolShiftType -> 1 | F2: ='SA-1'!$I$36 -> 1
A5: =LEN($A$2) -> 17 | B5: =LEN($B$2) -> 1 | C5: =LEN($C$2) -> 1 | D5: =LEN($D$2) -> 11 | E5: =LEN($E$2) -> 1 | F5: =LEN($F$2) -> 1

Sheet Clean_SA_1 _SchoolLandInfo
A1: SA_1_ID | B1: SchoolLandOwnershipType_ID | C1: SchoolLandType_ID | D1: SchoolCompound_Length_Feet | E1: SchoolCompound_Width_Feet | F1: SchoolCompound_Area_Arca
A2: =SA_1_ID -> 31022014180018001 | B2: =Selected_LandOwnership -> 1 | C2: =IF(Selected_LandType>0,Selected_LandType,"") -> 2 | D2: ='SA-1'!$E$45 -> 0 | E2: ='SA-1'!$H$45 -> 0 | F2: ='SA-1'!$L$45 -> 9.84
A5: =LEN($A$2) -> 17 | B5: =LEN($B$2) -> 1 | C5: =LEN($C$2) -> 1 | D5: =LEN($D$2) -> 1 | E5: =LEN($E$2) -> 1 | F5: =LEN($F$2) -> 4

Sheet Clean_SA_1 Facilities_Info
A1: SA_1_FacilityID | B1: SA_1_ID | C1: Facility_ID | E1: Facility_Capacity
A2: =B2&C2 -> 310220141800180011 | B2: =SA_1_ID -> 31022014180018001 | C2: ='SA-1'!$G$50 -> 1 | D2: FourSeated_Table | E2: ='SA-1'!$F$50 -> 41
A3: =B3&C3 -> 310220141800180012 | B3: =SA_1_ID -> 31022014180018001 | C3: ='SA-1'!$L$50 -> 2 | D3: FourSeated_Chair | E3: ='SA-1'!$K$50 -> 41
A4: =B4&C4 -> 310220141800180013 | B4: =SA_1_ID -> 31022014180018001 | C4: ='SA-1'!$G$52 -> 3 | D4: ThreeSeated_Table | E4: ='SA-1'!$F$52 -> 218
A5: =B5&C5 -> 310220141800180014 | B5: =SA_1_ID -> 31022014180018001 | C5: ='SA-1'!$L$52 -> 4 | D5: ThreeSeated_Chair | E5: ='SA-1'!$K$52 -> 218
A6: =B6&C6 -> 310220141800180017 | B6: =SA_1_ID -> 31022014180018001 | C6: ='SA-1'!$G$56 -> 7 | D6: TwoSeated_Table | E6: ='SA-1'!$F$56 -> 184
A7: =B7&C7 -> 310220141800180016 | B7: =SA_1_ID -> 31022014180018001 | C7: ='SA-1'!$L$54 -> 6 | D7: TwoSeated_Chair | E7: ='SA-1'!$K$54 -> 0
A8: =B8&C8 -> 310220141800180017 | B8: =SA_1_ID -> 31022014180018001 | C8: ='SA-1'!$G$56 -> 7 | D8: OneSeated_Table | E8: ='SA-1'!$F$56 -> 184
A9: =B9&C9 -> 310220141800180018 | B9: =SA_1_ID -> 31022014180018001 | C9: ='SA-1'!$L$56 -> 8 | D9: OneSeated_Chair | E9: ='SA-1'!$K$56 -> 184
